Workbook

Sheet LIST
A1: App ID | B1: App Name | C1: FME App Owner | D1: FME IT LEAD | E1: Cognizant App Owner Name | F1: Cognizant App Primary POC | G1: Type | H1: Link to Roster sheet
A2: 535 | B2: Global ComplianceWire - Quality & Regulatory Training | C2: dirk.malland@freseniusmedicalcare.com | D2: amy.green@freseniusmedicalcare.com | E2: Arun Kumar S Arun.KumarS4@cognizant.com | F2: Arun Kumar S Arun.KumarS4@cognizant.com | G2: 8x5 | H2: Others!A1
A3: 124 | B3: Mobile: CSM App | C3: Ritesh Nagori | D3: joerg.ludwig@freseniusmedicalcare.com | E3: Arunprasath Arunprasath.S2@cognizant.com | F3: Thangappan, Arunpandi Arunpandi.Thangappan@cognizant.com | G3: 24x5 | H3: Others!A1
A4: 127 | B4: Mobile: One App | C4: Ritesh Nagori | D4: ildiko-kinga.peter@freseniusmedicalcare.com | E4: Arunprasath Arunprasath.S2@cognizant.com | F4: Arunprasath Arunprasath.S2@cognizant.com | G4: 8x5 | H4: Others!A1
A5: 128 | B5: Mobile: One App Desktop | C5: Ritesh Nagori | D5: ildiko-kinga.peter@freseniusmedicalcare.com | E5: Arunprasath Arunprasath.S2@cognizant.com | F5: Vasudevan, Vishnu Vishnu.Vasudevan3@cognizant.com | G5: 8x5 | H5: Others!A1
A6: 129 | B6: Mobile: PID | C6: Ritesh Nagori | D6: alexander.wagner@freseniusmedicalcare.com | E6: Arunprasath Arunprasath.S2@cognizant.com | F6: Arunprasath Arunprasath.S2@cognizant.com | G6: 8x5 | H6: Others!A1
A7: 518 | B7: SleepSafeHarmony 2 EN | C7: Ritesh Nagori | D7: ildiko-kinga.peter@freseniusmedicalcare.com | E7: Arunprasath Arunprasath.S2@cognizant.com | F7: Arunprasath Arunprasath.S2@cognizant.com | G7: 16x5 | H7: Others!A1
A8: 140 | B8: Seeburger | C8: Ritesh Nagori | D8: Kondal.Reddy.Kasireddy@freseniusmedicalcare.com | E8: Atanu Atanu.Sadhukhan@cognizant.com | F8: Joyson A Joyson.A@cognizant.com | G8: 24x7 | H8: Others!A1
A9: 142 | B9: App Connect (Cast Iron) | C9: Ritesh Nagori | D9: Panthalarajan.Nagarethinam@freseniusmedicalcare.com | E9: Atanu Atanu.Sadhukhan@cognizant.com | F9: Srivarsha Gadipelli Srivarsha.Gadipelli@cognizant.com | G9: 8x5 | H9: Others!A1
A10: 111 | B10: Trackwise (QTRAK) | C10: Ritesh Nagori | D10: guruprasad.subbarayalu@freseniusmedicalcare.com | E10: Manjunath R Manjunath.R3@cognizant.com | F10: Nagraj LNU Nagraj.LNU@cognizant.com | G10: 24x5 | H10: Others!A1
A11: 120 | B11: JIRA - FME EQMS | C11: Ritesh Nagori | D11: mahammed.zubair@freseniusmedicalcare.com | E11: Vinish VinishKumar.V.M@cognizant.com | F11: Jeevam Empati Jeevan.Empati@cognizant.com | G11: 8x5 | H11: Others!A1
A12: 121 | B12: JIRA - FME QREM - CAPA Management | C12: Ritesh Nagori | D12: mahammed.zubair@freseniusmedicalcare.com | E12: Vinish VinishKumar.V.M@cognizant.com | F12: Jeevam Empati Jeevan.Empati@cognizant.com | G12: 8x5 | H12: Others!A1
A13: 122 | B13: JIRA / Service Desk - FME Technet/HR Operations | C13: Ritesh Nagori | D13: nitin.sane@freseniusmedicalcare.com | E13: Vinish VinishKumar.V.M@cognizant.com | F13: Jeevam Empati Jeevan.Empati@cognizant.com | G13: 24x5 | H13: Others!A1
... A32: 150 | B32: Modern Requirements | C32: Olivier de Bruijn | D32: Olivier.deBruijn@freseniusmedicalcare.com | E32: Murali Yenamala Gopala.YenamalaMurali@cognizant.com | F32: Murali Yenamala Gopala.YenamalaMurali@cognizant.com | G32: 8x5 | H32: Others!A1
A33: 537 | B33: GPDM Subversion | C33: harald.villinger_x000D_ michael.baunach | D33: harald.villinger@freseniusmedicalcare.com michael.baunach@freseniusmedicalcare.com | E33: Thiruvengadam Thiruvengadam.TC@cognizant.com | F33: Naren Elango Naren.Elango@cognizant.com | G33: 24x5
A34: 906 | B34: Azure: ICC External | C34: Ritesh Nagori | D34: andreas.klaus@freseniusmedicalcare.com | E34: Vinish VinishKumar.V.M@cognizant.com | F34: Vinish VinishKumar.V.M@cognizant.com | G34: 8x5 | H34: Others!A1
A35: 907 | B35: Azure: ICC Training Material | C35: Ritesh Nagori | D35: andreas.klaus@freseniusmedicalcare.com | E35: Vinish VinishKumar.V.M@cognizant.com | F35: Silpa C C.Silpa@cognizant.com | G35: 8x5 | H35: Others!A1
A36: 908 | B36: IQVIA | C36: Ritesh Nagori | D36: guruprasad.subbarayalu@freseniusmedicalcare.com | E36: Manjunath R Manjunath.R3@cognizant.com | F36: Nagraj LNU Nagraj.LNU@cognizant.com | G36: 24x5 | H36: Others!A1
U46: larion

Sheet PLM
A1: Shift # | B1: Support Type | D1: 1 | I1: 2 | N1: 3 | S1: 4
A2: Shift Timing (IST) | D2: 6:00 AM – 3:00 PM (IST) | I2: 1:00 PM – 10:00 PM (IST) | N2: 6:30 PM – 3:30 AM (IST) | S2: 9:30 PM – 6:30 AM (IST)
A3: Shift Timing (CET) | D3: 1:30 AM – 10:30 AM (CET) | I3: 9:30 AM – 06:30 PM (CET) | N3: 2:00 PM – 11:00 PM (CET) | S3: 5:00 PM – 02:00 AM (CET)
A4: Shift Timing (EST) | D4: 7:30 PM – 4:30 AM (EST) | I4: 3:30 AM – 12:30 PM (EST) | N4: 8:00 AM – 5:00 PM (EST) | S4: 08:00 AM – 5:00 PM (PST)
A5: Application | D5: Associate Name | E5: FME - Email | F5: CTS ID | G5: Contact No | H5: Type | I5: Associate Name | J5: FME - Email | K5: CTS ID | L5: Contact No | M5: Type | N5: Associate Name | O5: FME - Email | P5: CTS ID | Q5: Contact No | R5: Type | S5: Associate Name | T5: FME - Email | U5: CTS ID | V5: Contact No | W5: Type
A6: Polarion | B6: 24*5 | C6: Renate / Miklos | D6: Kaushik Kandagatla | E6: kandagatla.kaushik@freseniusmedicalcare.com | F6: 2261768 | G6: +91 9398549213 | H6: Primary | I6: Sagar Kaware | J6: sagar.kaware@freseniusmedicalcare.com | K6: 696947 | L6: +49 15124631682 | M6: Primary | N6: Gowthami Konduri | O6: gowthami.konduri@freseniusmedicalcare.com | P6: 2068067 | Q6: +1 4376613375 | R6: Primary | S6: Divya Unnikrishnan | T6: divya.unnikrishnan@freseniusmedicalcare.com | U6: 470861 | V6: +1 77 86 32 0220 | W6: Primary
A7: Polarion | I7: Diksha Kokadwar | J7: diksha.kokadwar@freseniusmedicalcare.com | K7: 2262064 | L7: +91 8600482848 | M7: Primary | N7: Divya Unnikrishnan | O7: divya.unnikrishnan@freseniusmedicalcare.com | P7: 470861 | Q7: +1 77 86 32 0220 | R7: Primary | S7: Gowthami Konduri | T7: gowthami.konduri@freseniusmedicalcare.com | U7: 2068067 | V7: +1 4376613375 | W7: Primary
A8: TWX | B8: 24*5 | C8: Surender / Renate | D8: Bhargavi Alapati | E8: alapati.bhargavi@freseniusmedicalcare.com | F8: 2428440 | G8: +91 7702394457 | H8: Primary | I8: Anoop Sarkar | J8: anoopanand.sarkar@freseniusmedicalcare.com | K8: 2228647 | L8: +91 9834330308 | M8: Primary | N8: Gowthami Konduri | O8: gowthami.konduri@freseniusmedicalcare.com | P8: 2068067 | Q8: +1 4376613375 | R8: Primary | S8: Divya Unnikrishnan | T8: divya.unnikrishnan@freseniusmedicalcare.com | U8: 470861 | V8: +1 77 86 32 0220 | W8: Primary
A9: TWX | I9: Manoj Yamala | J9: manoj.yamala@freseniusmedicalcare.com | K9: 2096374 | L9: +91 7730932926 | M9: Primary | N9: Divya Unnikrishnan | O9: divya.unnikrishnan@freseniusmedicalcare.com | P9: 470861 | Q9: +1 77 86 32 0220 | R9: Primary | S9: Gowthami Konduri | T9: gowthami.konduri@freseniusmedicalcare.com | U9: 2068067 | V9: +1 4376613375 | W9: Primary
A10: Windchill GPDM/QDOK | B10: 24*5 | C10: Ravi/ Ragu/ Ritesh | D10: Bhargavi Alapati | E10: alapati.bhargavi@freseniusmedicalcare.com | F10: 2428440 | G10: +91 7702394457 | H10: Primary | I10: Spoorthy HR | J10: spoorthy.hr1@freseniusmedicalcare.com | K10: 2458610 | L10: +91 91085 55623 | M10: Primary | N10: Gowthami Konduri | O10: gowthami.konduri@freseniusmedicalcare.com | P10: 2068067 | Q10: +1 4376613375 | R10: Primary | S10: Divya Unnikrishnan | T10: divya.unnikrishnan@freseniusmedicalcare.com | U10: 470861 | V10: +1 77 86 32 0220 | W10: Primary
A11: Windchill GPDM | I11: Shashank Purohit | J11: shashank.purohit1@freseniusmedicalcare.com | K11: 2134110 | L11: +91 8826245403 | M11: Primary | N11: Divya Unnikrishnan | O11: divya.unnikrishnan@freseniusmedicalcare.com | P11: 470861 | Q11: +1 77 86 32 0220 | R11: Primary | S11: Gowthami Konduri | T11: gowthami.konduri@freseniusmedicalcare.com | U11: 2068067 | V11: +1 4376613375 | W11: Primary
A12: Windchill GPDM | I12: Akriti Vats | J12: akriti.vats@freseniusmedicalcare.com | K12: 2177684 | L12: +91 8510070608 | M12: Primary | N12: Sakshi Bhuse | O12: sakshirajshekhar.bhuse@freseniusmedicalcare.com | P12: 2459296 | Q12: +91 9834314522 | R12: Primary | S12: Sakshi Bhuse | T12: sakshirajshekhar.bhuse@freseniusmedicalcare.com | U12: 2459296 | V12: +91 9834314522 | W12: Primary
A13: Windchill GPDM | I13: Gourav Patnaik | J13: gouravkumar.patnaik@freseniusmedicalcare.com | L13: +91 9853142158 | M13: Primary
A14: Windchill GPDM | I14: Goutam BM | J14: goutam.bhadravti-mohan@freseniusmedicalcare.com | K14: 2469233 | L14: +91 9632318013 | M14: Primary
A15: Windchill GPDM/QDOK | I15: Nikhil Bhiste | J15: nikhil.bhiste@freseniusmedicalcare.com | K15: 2425958 | L15: +91 8149828774 | M15: Primary
A16: Windchill GPDM | I16: Venkata Subba Reddy Varra | J16: venkatasubbareddy.varra@freseniusmedicalcare.com | K16: 2425983 | L16: +91 7036172413 | M16: Primary
A17: Windchill GPDM | I17: Vinoth Kumar | J17: vinothkumar.udhayakumar@freseniusmedicalcare.com | L17: +91 9551558559 | M17: Primary
A18: Windchill NA | B18: 24*5 | C18: Ravi | D18: Vaibhav Kolekar | E18: kolekar.vaibhavsunil@freseniusmedicalcare.com | F18: 2261809 | G18: +91 9067233323 | H18: Primary | I18: Prasanthi Allam | J18: allam.prasanthi@freseniusmedicalcare.com | K18: 2276700 | L18: +91 6300723778 | M18: Primary | N18: Gowthami Konduri | O18: gowthami.konduri@freseniusmedicalcare.com | P18: 2068067 | Q18: +1 4376613375 | R18: Primary | S18: Divya Unnikrishnan | T18: divya.unnikrishnan@freseniusmedicalcare.com | U18: 470861 | V18: +1 77 86 32 0220 | W18: Primary
A19: Windchill NA | I19: Pushpa Patil | J19: pushpa.gajananpatil@freseniusmedicalcare.com | K19: 2436313 | L19: +91 8208830014 | M19: Primary | N19: Divya Unnikrishnan | O19: divya.unnikrishnan@freseniusmedicalcare.com | P19: 470861 | Q19: +1 77 86 32 0220 | R19: Primary | S19: Gowthami Konduri | T19: gowthami.konduri@freseniusmedicalcare.com | U19: 2068067 | V19: +1 4376613375 | W19: Primary

Sheet PLM_19-Mar-2026
A1: Shift # | B1: Support Type | D1: 1 | I1: 2 | N1: 3 | S1: 4
A2: Shift Timing (IST) | D2: 6:00 AM – 3:00 PM (IST) | I2: 1:00 PM – 10:00 PM (IST) | N2: 6:30 PM – 3:30 AM (IST) | S2: 9:30 PM – 6:30 AM (IST)
A3: Shift Timing (CET) | D3: 1:30 AM – 10:30 AM (CET) | I3: 9:30 AM – 06:30 PM (CET) | N3: 2:00 PM – 11:00 PM (CET) | S3: 5:00 PM – 02:00 AM (CET)
A4: Shift Timing (EST) | D4: 7:30 PM – 4:30 AM (EST) | I4: 3:30 AM – 12:30 PM (EST) | N4: 8:00 AM – 5:00 PM (EST) | S4: 08:00 AM – 5:00 PM (PST)
A5: Application | D5: Associate Name | E5: FME - Email | F5: CTS ID | G5: Contact No | H5: Type | I5: Associate Name | J5: FME - Email | K5: CTS ID | L5: Contact No | M5: Type | N5: Associate Name | O5: FME - Email | P5: CTS ID | Q5: Contact No | R5: Type | S5: Associate Name | T5: FME - Email | U5: CTS ID | V5: Contact No | W5: Type
A6: Polarion | B6: 24*5 | C6: Renate / Miklos | D6: Anoop Sarkar | E6: anoopanand.sarkar@freseniusmedicalcare.com | F6: 2228647 | G6: +91 9834330308 | H6: Primary | I6: Sagar Kaware | J6: sagar.kaware@freseniusmedicalcare.com | K6: 696947 | L6: +49 15124631682 | M6: Primary | N6: Gowthami Konduri | O6: gowthami.konduri@freseniusmedicalcare.com | P6: 2068067 | Q6: +1 4376613375 | R6: Primary | S6: Divya Unnikrishnan | T6: divya.unnikrishnan@freseniusmedicalcare.com | U6: 470861 | V6: +1 77 86 32 0220 | W6: Primary
A7: Polarion | I7: Diksha Kokadwar | J7: diksha.kokadwar@freseniusmedicalcare.com | K7: 2262064 | L7: +91 8600482848 | M7: Primary | N7: Gowthami Konduri | O7: gowthami.konduri@freseniusmedicalcare.com | P7: 2068067 | Q7: +1 4376613375 | R7: Primary | S7: Divya Unnikrishnan | T7: divya.unnikrishnan@freseniusmedicalcare.com | U7: 470861 | V7: +1 77 86 32 0220 | W7: Primary
A8: TWX | B8: 24*5 | C8: Surender / Renate | D8: Anoop Sarkar | E8: anoopanand.sarkar@freseniusmedicalcare.com | F8: 2228647 | G8: +91 9834330308 | H8: Primary | N8: Gowthami Konduri | O8: gowthami.konduri@freseniusmedicalcare.com | P8: 2068067 | Q8: +1 4376613375 | R8: Primary | S8: Divya Unnikrishnan | T8: divya.unnikrishnan@freseniusmedicalcare.com | U8: 470861 | V8: +1 77 86 32 0220 | W8: Primary
A9: Windchill GPDM | B9: 24*5 | C9: Ravi/ Ragu/ Ritesh | D9: Anoop Sarkar | E9: anoopanand.sarkar@freseniusmedicalcare.com | F9: 2228647 | G9: +91 9834330308 | H9: Primary | I9: Akriti Vats | J9: akriti.vats@freseniusmedicalcare.com | K9: 2177684 | L9: +91 8510070608 | M9: Primary | N9: Gowthami Konduri | O9: gowthami.konduri@freseniusmedicalcare.com | P9: 2068067 | Q9: +1 4376613375 | R9: Primary | S9: Divya Unnikrishnan | T9: divya.unnikrishnan@freseniusmedicalcare.com | U9: 470861 | V9: +1 77 86 32 0220 | W9: Primary
A10: Windchill GPDM | I10: Sakshi Bhuse | J10: sakshirajshekhar.bhuse@freseniusmedicalcare.com | K10: 2459296 | L10: +91 9834314522 | M10: Primary
A11: Windchill GPDM | I11: Nikhil Bhiste | J11: nikhil.bhiste@freseniusmedicalcare.com | K11: 2425958 | L11: +91 8149828774 | M11: Primary
A12: Windchill GPDM/QDOK | I12: Jhansi Gowroju | J12: gowroju.jhansi@freseniusmedicalcare.com | K12: 2424270 | L12: +91 8498809471 | M12: Primary
A13: Windchill NA | B13: 24*5 | C13: Ravi | D13: Anoop Sarkar | E13: anoopanand.sarkar@freseniusmedicalcare.com | F13: 2228647 | G13: +91 9834330308 | H13: Primary | I13: Vaibhav Kolekar | J13: kolekar.vaibhavsunil@freseniusmedicalcare.com | K13: 2261809 | L13: +91 9067233323 | M13: Primary | N13: Gowthami Konduri | O13: gowthami.konduri@freseniusmedicalcare.com | P13: 2068067 | Q13: +1 4376613375 | R13: Primary | S13: Divya Unnikrishnan | T13: divya.unnikrishnan@freseniusmedicalcare.com | U13: 470861 | V13: +1 77 86 32 0220 | W13: Primary

Sheet PLM_20-Mar-2026
A1: Shift # | B1: Support Type | D1: 1 | I1: 2 | N1: 3 | S1: 4
A2: Shift Timing (IST) | D2: 6:00 AM – 3:00 PM (IST) | I2: 1:00 PM – 10:00 PM (IST) | N2: 6:30 PM – 3:30 AM (IST) | S2: 9:30 PM – 6:30 AM (IST)
A3: Shift Timing (CET) | D3: 1:30 AM – 10:30 AM (CET) | I3: 9:30 AM – 06:30 PM (CET) | N3: 2:00 PM – 11:00 PM (CET) | S3: 5:00 PM – 02:00 AM (CET)
A4: Shift Timing (EST) | D4: 7:30 PM – 4:30 AM (EST) | I4: 3:30 AM – 12:30 PM (EST) | N4: 8:00 AM – 5:00 PM (EST) | S4: 08:00 AM – 5:00 PM (PST)
A5: Application | D5: Associate Name | E5: FME - Email | F5: CTS ID | G5: Contact No | H5: Type | I5: Associate Name | J5: FME - Email | K5: CTS ID | L5: Contact No | M5: Type | N5: Associate Name | O5: FME - Email | P5: CTS ID | Q5: Contact No | R5: Type | S5: Associate Name | T5: FME - Email | U5: CTS ID | V5: Contact No | W5: Type
A6: Polarion | B6: 24*5 | C6: Renate / Miklos | D6: Anoop Sarkar | E6: anoopanand.sarkar@freseniusmedicalcare.com | F6: 2228647 | G6: +91 9834330308 | H6: Primary | I6: Sagar Kaware | J6: sagar.kaware@freseniusmedicalcare.com | K6: 696947 | L6: +49 15124631682 | M6: Primary | N6: Gowthami Konduri | O6: gowthami.konduri@freseniusmedicalcare.com | P6: 2068067 | Q6: +1 4376613375 | R6: Primary | S6: Divya Unnikrishnan | T6: divya.unnikrishnan@freseniusmedicalcare.com | U6: 470861 | V6: +1 77 86 32 0220 | W6: Primary
A7: TWX | B7: 24*5 | C7: Surender / Renate | D7: Anoop Sarkar | E7: anoopanand.sarkar@freseniusmedicalcare.com | F7: 2228647 | G7: +91 9834330308 | H7: Primary | I7: Spoorthy HR | J7: spoorthy.hr1@freseniusmedicalcare.com | K7: 2458610 | L7: +91 91085 55623 | M7: Primary | N7: Gowthami Konduri | O7: gowthami.konduri@freseniusmedicalcare.com | P7: 2068067 | Q7: +1 4376613375 | R7: Primary | S7: Divya Unnikrishnan | T7: divya.unnikrishnan@freseniusmedicalcare.com | U7: 470861 | V7: +1 77 86 32 0220 | W7: Primary
A8: Windchill GPDM | D8: Anoop Sarkar | E8: anoopanand.sarkar@freseniusmedicalcare.com | F8: 2228647 | G8: +91 9834330308 | H8: Primary | I8: Shashank Purohit | J8: shashank.purohit1@freseniusmedicalcare.com | K8: 2134110 | L8: +91 8826245403 | M8: Primary | N8: Gowthami Konduri | O8: gowthami.konduri@freseniusmedicalcare.com | P8: 2068067 | Q8: +1 4376613375 | R8: Primary | S8: Divya Unnikrishnan | T8: divya.unnikrishnan@freseniusmedicalcare.com | U8: 470861 | V8: +1 77 86 32 0220 | W8: Primary
A9: Windchill GPDM/QDOK | I9: Spoorthy HR | J9: spoorthy.hr1@freseniusmedicalcare.com | K9: 2458610 | L9: +91 91085 55623 | M9: Primary
A10: Windchill NA | B10: 24*5 | C10: Ravi | D10: Anoop Sarkar | E10: anoopanand.sarkar@freseniusmedicalcare.com | F10: 2228647 | G10: +91 9834330308 | H10: Primary | I10: Pushpa Patil | J10: pushpa.gajananpatil@freseniusmedicalcare.com | K10: 2436313 | L10: +91 8208830014 | M10: Primary | N10: Gowthami Konduri | O10: gowthami.konduri@freseniusmedicalcare.com | P10: 2068067 | Q10: +1 4376613375 | R10: Primary | S10: Divya Unnikrishnan | T10: divya.unnikrishnan@freseniusmedicalcare.com | U10: 470861 | V10: +1 77 86 32 0220 | W10: Primary

Sheet Others
B2: Shift Timing | C2: Support Type | D2: 11:00 AM to 09:00 PM (IST) 06:30 AM to 04:30 PM (CET) 12:30 AM to 10:30 AM (EST) | J2: 06:00 AM to 04:00 PM (IST) 01:30 AM to 11:30 AM (CET) 07:30 PM to 05:30 AM (EST) | P2: 11:30 AM to 9:30 PM (IST) 07:00 AM to 06:00 PM (CET) 01:00 AM to 11:00 AM (EST) | V2: 05:30 PM to 3:30 AM (IST) 01:00 PM to 11:00 PM (CET) 07:00 AM to 05:00 PM (EST) | AB2: 09:00 PM – 07:00 AM (IST) 04:30 PM – 2:30 AM (CET) 10:30 AM – 08:30 PM (EST)
A3: ID | B3: App | C3: Support Type | D3: Associate Name | E3: FME - Email | F3: Associate ID | G3: Contact No | H3: Type | J3: Associate Name | K3: FME - Email | L3: Associate ID | M3: Contact No | N3: Type | P3: Associate Name | Q3: FME - Email | R3: Associate ID | S3: Contact No | T3: Type | V3: Associate Name | W3: FME - Email | X3: Associate ID | Y3: Contact No | Z3: Type | AB3: Associate Name | AC3: FME - Email | AD3: Associate ID | AE3: Contact No | AF3: Type
A4: 535 | B4: Global ComplianceWire - Quality & Regulatory Training | C4: =VLOOKUP(A4,LIST!$A$1:$H$33,7,0) -> 8x5 | D4: Arunkumar S | E4: arunkumar.s@freseniusmedicalcare.com | G4: "+91-9940699661" | H4: Primary
A5: 124 | B5: Mobile: CSM App | C5: 8x5 | D5: Thangappan, Arunpandi | E5: arunpandi.thangappan@freseniusmedicalcare.com | G5: "+91-8610088276" | H5: Primary
A6: 127 | B6: Mobile: One App | C6: =VLOOKUP(A6,LIST!$A$1:$H$33,7,0) -> 8x5 | D6: Arunprasath Sivasamy | E6: arunprasath.s@freseniusmedicalcare.com | G6: "+91-9003701020" | H6: Primary
A7: 128 | B7: Mobile: One App Desktop | C7: =VLOOKUP(A7,LIST!$A$1:$H$33,7,0) -> 8x5 | D7: Arunprasath Sivasamy | E7: arunprasath.s@freseniusmedicalcare.com | G7: "+91-9003701020" | H7: Primary
A8: 129 | B8: Mobile: PID | C8: =VLOOKUP(A8,LIST!$A$1:$H$33,7,0) -> 8x5 | D8: Arunprasath Sivasamy | E8: arunprasath.s@freseniusmedicalcare.com | G8: "+91-9003701020" | H8: Primary
A9: 120 | B9: JIRA - FME EQMS | C9: =VLOOKUP(A9,LIST!$A$1:$H$33,7,0) -> 8x5 | D9: Jeevan Empati Vaishali Patel Vinish Kumar | E9: jeevan.empati@freseniusmedicalcare.com vinishkumar.vijayakumarmallika@freseniusmedicalcare.com vaishali.patel@freseniusmedicalcare.com | G9: +91-9030962553 +91-9009419200 +91-8940781978 | H9: Primary Secondary Secondary
A10: 121 | B10: JIRA - FME QREM - CAPA Management | C10: =VLOOKUP(A10,LIST!$A$1:$H$33,7,0) -> 8x5 | D10: Jeevan Empati Vaishali Patel Vinish Kumar | E10: jeevan.empati@freseniusmedicalcare.com vinishkumar.vijayakumarmallika@freseniusmedicalcare.com vaishali.patel@freseniusmedicalcare.com | G10: +91-9030962553 +91-9009419200 +91-8940781978 | H10: Primary Secondary Secondary
A11: 116 | B11: Azure: ICC Portal | C11: =VLOOKUP(A11,LIST!$A$1:$H$33,7,0) -> 8x5 | D11: Silpa C | E11: silpa.c@freseniusmedicalcare.com | G11: +91-9496719262 | H11: Primary
A12: 117 | B12: BI SQL Cluster / FME - Epur | C12: =VLOOKUP(A12,LIST!$A$1:$H$33,7,0) -> 8x5 | P12: Rajesh Kumar E Ganesh G A, Prasanth | Q12: rajeshkumar.e@freseniusmedicalcare.com prasanth.a@freseniusmedicalcare.com ganesh.g@freseniusmedicalcare.com | S12: "+91-8825996657" "+91-9500901036" "+91 9698782477" | T12: Primary Secondary Secondary
A13: 119 | B13: CQT - Configuration & Quotation Tool | C13: =VLOOKUP(A13,LIST!$A$1:$H$33,7,0) -> 8x5 | D13: Pooja PH Deva Darshini S Duvvi Vinod Kumar | E13: pooja.ph@freseniusmedicalcare.com deva.darshinis@freseniusmedicalcare.com vinodkumar.duvvi@freseniusmedicalcare.com | G13: +91-8190882020 +91-7981947799 +91-7010488802 | H13: Primary Secondary Secondary
A14: 150 | B14: Modern Requirements | C14: =VLOOKUP(A14,LIST!$A$1:$H$33,7,0) -> 8x5 | D14: Pooja PH | E14: pooja.ph@freseniusmedicalcare.com | G14: +91-8190882020 | H14: Secondary | V14: Yenamala Murali | W14: muraligopalakrishna.yenamala@freseniusmedicalcare.com | Y14: "+1-5083081308" | Z14: Primary
A15: 518 | B15: SleepSafeHarmony 2 EN | C15: 8x5 | D15: Arunprasath Sivasamy | E15: arunprasath.s@freseniusmedicalcare.com | G15: "+91-9003701020" | H15: Primary
A16: 142 | B16: App Connect (Cast Iron) | C16: =VLOOKUP(A16,LIST!$A$1:$H$33,7,0) -> 8x5 | D16: Gadipelli, Srivarsha | E16: srivarsha.gadipelli@freseniusmedicalcare.com | G16: "+91-8328479334"
A17: 152 | B17: Viima | C17: =VLOOKUP(A17,LIST!$A$1:$H$33,7,0) -> 8x5 | V17: Naren Elango | W17: naren.elango@freseniusmedicalcare.com | X17: 425559 | Y17: +91-9952973703 | Z17: Primary
A18: 52 | B18: Salesforce Health Cloud - Shield, Field Service Lightning | C18: =VLOOKUP(A18,LIST!$A$1:$H$33,7,0) -> #N/A | D18: Hariharan, Varsha | E18: varsha.hariharan@freseniusmedicalcare.com | G18: "+91-9047027783" | V18: Vinay Kumar | W18: vinay.kumar@freseniusmedicalcare.com | X18: 698968 | Y18: +1 4376799099 | Z18: Primary
A19: 114 | B19: Salesforce Integrations (US CE Commercial) | C19: =VLOOKUP(A19,LIST!$A$1:$H$33,7,0) -> 16x5 | D19: Hariharan, Varsha | E19: varsha.hariharan@freseniusmedicalcare.com | G19: "+91-9047027783" | V19: Vinay Kumar | W19: vinay.kumar@freseniusmedicalcare.com | X19: 698968 | Y19: +1 4376799099 | Z19: Primary
A20: 133 | B20: Clinic Backroom Supply (RTG Orders / RTG Supplies) | C20: =VLOOKUP(A20,LIST!$A$1:$H$33,7,0) -> 16x5 | D20: Hariharan, Varsha | E20: varsha.hariharan@freseniusmedicalcare.com rohit.prasad@freseniusmedicalcare.com | G20: "+91-9047027783" "+91-7663909594" | V20: Vinay Kumar | W20: vinay.kumar@freseniusmedicalcare.com | X20: 698968 | Y20: +1 4376799099 | Z20: Primary
A21: 134 | B21: SalesForce (CE US Commercial) | C21: =VLOOKUP(A21,LIST!$A$1:$H$33,7,0) -> 16x5 | D21: Hariharan, Varsha | E21: varsha.hariharan@freseniusmedicalcare.com | G21: "+91-9047027783" | V21: Vinay Kumar | W21: vinay.kumar@freseniusmedicalcare.com | X21: 698968 | Y21: +1 4376799099 | Z21: Primary
A22: 135 | B22: Salesforce NxStage Medical | C22: =VLOOKUP(A22,LIST!$A$1:$H$33,7,0) -> 16x5 | D22: Hariharan, Varsha | E22: varsha.hariharan@freseniusmedicalcare.com | G22: "+91-9047027783" | V22: Vinay Kumar | W22: vinay.kumar@freseniusmedicalcare.com | X22: 698968 | Y22: +1 4376799099 | Z22: Primary
A23: 137 | B23: Salesforce - Conga (LATAM) | C23: =VLOOKUP(A23,LIST!$A$1:$H$33,7,0) -> 16x5 | D23: Rohit Prasad | E23: rohit.prasad@freseniusmedicalcare.com | G23: "+91-7663909594" | J23: Solanki, Sagar | K23: sagar.solanki@freseniusmedicalcare.com | M23: "+91-909287017" | N23: on call | V23: Vinay Kumar | W23: vinay.kumar@freseniusmedicalcare.com | X23: 698968 | Y23: +1 4376799099 | Z23: Primary
A24: 139 | B24: Salesforce - Conga (CE US Commercial) | C24: =VLOOKUP(A24,LIST!$A$1:$H$33,7,0) -> 16x5 | D24: Rohit Prasad | E24: rohit.prasad@freseniusmedicalcare.com | G24: "+91-7663909594" | J24: Solanki, Sagar | K24: sagar.solanki@freseniusmedicalcare.com | M24: "+91-909287017" | N24: on call | V24: Vinay Kumar | W24: vinay.kumar@freseniusmedicalcare.com | X24: 698968 | Y24: +1 4376799099 | Z24: Primary
A25: 538 | B25: gpm-jenkins-prod-Diamond | C25: =VLOOKUP(A25,LIST!$A$1:$H$33,7,0) -> 24x5 | E25: App is listed as 24X5 , we have concurrence from Harald to operate in single shift for some time based on volume we will add people across shifts. Shared the email with Ritesh for reference | V25: Naren Elango | W25: naren.elango@freseniusmedicalcare.com | X25: 425559 | Y25: +91-9952973703 | Z25: Primary
A26: 111 | B26: Trackwise (QTRAK) | C26: =VLOOKUP(A26,LIST!$A$1:$H$33,7,0) -> 24x5 | J26: Sreevarsha B Vinod Kumar | K26: sreevarsha.vuppala@freseniusmedicalcare.com bvinod.kumar@freseniusmedicalcare.com | M26: +91-9000094243 +91-6369597827 | N26: Primary Secondary | P26: Nagraj Manjunath R | Q26: nagraj.lnu@freseniusmedicalcare.com manjunath.r@freseniusmedicalcare.com | S26: +91-7760825713 +91-7411861544 | T26: Primary | V26: SaiNivedita | W26: sainivedita.venishetty@freseniusmedicalcare.com | Y26: +1 (401) 688-0356 | Z26: Primary
A27: 122 | B27: JIRA / Service Desk - FME Technet/HR Operations | C27: =VLOOKUP(A27,LIST!$A$1:$H$33,7,0) -> 24x5 | D27: Jeevan Empati Vaishali Patel Vinish Kumar | E27: jeevan.empati@freseniusmedicalcare.com vinishkumar.vijayakumarmallika@freseniusmedicalcare.com vaishali.patel@freseniusmedicalcare.com | G27: +91-9030962553 +91-9009419200 +91-8940781978 | H27: Primary Secondary Secondary | J27: Ramya R Vaishali Patel Betty Theresa | K27: ramya.r@freseniusmedicalcare.com vaishali.patel@freseniusmedicalcare.com | M27: "+91-7092048459" "+91-9009419200" | N27: On call
A28: 106 | B28: Artifactory | C28: =VLOOKUP(A28,LIST!$A$1:$H$33,7,0) -> 24x5 | E28: App is listed as 24X5 , we have concurrence from Harald to operate in single shift for some time based on volume we will add people across shifts. Shared the email with Ritesh for reference | V28: Naren Elango | W28: naren.elango@freseniusmedicalcare.com | X28: 425559 | Y28: +91-9952973703 | Z28: Primary
A29: 108 | B29: Polarion | C29: =VLOOKUP(A29,LIST!$A$1:$H$33,7,0) -> 24x5 | D29: Added in PLM Sheet
A30: 109 | B30: PTC ThingWorx Navigate | C30: =VLOOKUP(A30,LIST!$A$1:$H$33,7,0) -> 24x5 | D30: Added in PLM Sheet
A31: 112 | B31: PTC Windchill GPDM | C31: =VLOOKUP(A31,LIST!$A$1:$H$33,7,0) -> 24x5 | D31: Added in PLM Sheet
A32: 113 | B32: PTC Windchill NA | C32: =VLOOKUP(A32,LIST!$A$1:$H$33,7,0) -> 24x5 | D32: Added in PLM Sheet
A33: 906 | B33: Azure: ICC External | C33: 8x5 | D33: Vinishkumar Yasaswini Biragi Ravichandran | E33: vinishkumar.vijayakumarmallika@freseniusmedicalcare.com yasaswini.biragi@freseniusmedicalcare.com ravichandran.ponnusamy@freseniusmedicalcare.com | G33: +91- 8940781978 +91-9390554508 +91- 9940061650 | H33: Primary Primary Secondary
A34: 907 | B34: Azure: Training Material | C34: 8x5 | D34: Silpa C Vinishkumar | E34: silpa.c@freseniusmedicalcare.com vinishkumar.vijayakumarmallika@freseniusmedicalcare.com | G34: +91-9496719262 +91- 8940781978 | H34: Primary Secondary
A35: 537 | B35: GPDM Subversion | C35: 24x5 | E35: Naren to get the email to share the concurrence | V35: Naren Elango | W35: naren.elango@freseniusmedicalcare.com | X35: 425559 | Y35: +91-9952973703 | Z35: Primary
A36: 908 | B36: IQVIA RIMS | C36: 24x5 | J36: Sreevarsha | K36: sreevarsha.vuppala@freseniusmedicalcare.com | M36: +91-9000094243 | N36: Primary | P36: Nagraj Manjunath R | Q36: nagraj.lnu@freseniusmedicalcare.com manjunath.r@freseniusmedicalcare.com | S36: +91-7760825713 +91-7411861544 | T36: Primary | V36: SaiNivedita | W36: sainivedita.venishetty@freseniusmedicalcare.com | Y36: +1 (401) 688-0356 | Z36: Primary
A37: 140 | B37: Seeburger | C37: 24x7 | D37: Seebuger L1.5'!A1 | J37: Seebuger L1.5'!A1 | P37: Joyson A (Seeburger) Ravi Babu Gurram (SAP) | Q37: joyson.a@freseniusmedicalcare.com ravibabu.gurram@freseniusmedicalcare.com | R37: 769836 817399 | S37: +91-9110738444 +91-9980077330 | T37: Primary Primary | V37: Seebuger L1.5'!A1 | AB37: Abdul Kalam Akula (SAP) | AC37: abdulkalam.akula@freseniusmedicalcare.com | AD37: 498127 | AE37: +1-2345675554 | AF37: Primary

Sheet PLM (2)
A1: Shift # | C1: 1 | H1: 2 | M1: 3 | R1: 4
A2: Shift Timing | B2: IST | C2: 6:00 AM – 3:00 PM (IST) | H2: 10:00 AM – 7:00 PM (IST) | M2: 1:00 PM – 10:00 PM (IST) | R2: 7:00 PM – 4:00 AM (IST)
A3: Shift Timing | B3: CET | C3: 2:30 AM – 11:30 AM (CET) | H3: 06:30 AM – 3:30 PM (CET) | M3: 9:30 AM – 06:30 PM (CET) | R3: 3:30 PM – 12:30 AM (CET)
A4: Shift Timing | B4: EST | C4: 8:30 PM – 5:30 AM (EST) | H4: 00:30 AM – 9:30 AM (EST) | M4: 3:30 AM – 12:30 PM (EST) | R4: 9:30 AM – 6:30 PM (EST)
A5: App | C5: Associate Name | D5: FME - ZID | E5: Associate ID | F5: Contact No | G5: Type | H5: Associate Name | I5: FME - ZID | J5: Associate ID | K5: Contact No | L5: Type | M5: Associate Name | N5: FME - ZID | O5: Associate ID | P5: Contact No | Q5: Type | R5: Associate Name | S5: FME - ZID | T5: Associate ID | U5: Contact No | V5: Type
A6: Polarion | C6: Kaushik Kandagatla | D6: Z00662380 | E6: 2261768 | F6: +91 9398549213 | G6: Primary | H6: Diksha Kokadwar | I6: Z00662384 | J6: 2262064 | K6: +91 8600482848 | L6: Primary | M6: Sagar Kaware | N6: Z00664503 | O6: 696947 | P6: +49 15124631682 | Q6: Primary | R6: Gowthami Konduri | S6: Z00666701 | T6: 2068067 | U6: +1 4376613375 | V6: Secondary
A7: Polarion | B7: Renate / Miklos | H7: Manoj Yamala | I7: Z00662366 | J7: 2096374 | K7: +91 7730932926 | L7: Secondary | M7: Anoop Sarkar | N7: Z00666776 | O7: 2228647 | P7: +91 9834330308 | Q7: Secondary
A8: TWX | B8: Surender / Reanate | H8: Manoj Yamala | I8: Z00662366 | J8: 2096374 | K8: +91 7730932926 | L8: Primary | M8: Anoop Sarkar | N8: Z00666776 | O8: 2228647 | P8: +91 9834330308 | Q8: Primary | R8: Gowthami Konduri | S8: Z00666701 | T8: 2068067 | U8: +1 4376613375 | V8: Primary
A9: TWX | H9: Diksha Kokadwar | I9: Z00662384 | J9: 2262064 | K9: +91 8600482848 | L9: Secondary | M9: Sagar Kaware | N9: Z00664503 | O9: 696947 | P9: +49 15124631682 | Q9: Secondary
A10: GPDM | B10: Ritesh / Ravi | C10: Shashank Purohit | D10: Z00662372 | E10: 2134110 | F10: +91 8826245403 | G10: Primary | H10: Prasanthi Allam | I10: Z00662385 | J10: 2276700 | K10: +91 6300723778 | L10: Primary | M10: Venkata Subba Reddy Varra | N10: Z00662945 | O10: 2425983 | P10: +91 7036172413 | Q10: Primary | R10: Gowthami Konduri | S10: Z00666701 | T10: 2068067 | U10: +1 4376613375 | V10: Secondary
A11: GPDM | C11: Vaibhav Kolekar | D11: Z00662381 | E11: 2261809 | F11: +91 9067233323 | G11: Secondary | H11: Shahabaz Patel | I11: Z00664502 | J11: 2003109 | K11: +91 7350807999 | L11: Primary | M11: Bhargavi Alapati | N11: Z00663739 | O11: 2428440 | P11: +91 7702394457 | Q11: Primary
A12: GPDM | C12: Kaushik Kandagatla | D12: Z00662380 | E12: 2261768 | F12: +91 9398549213 | G12: Secondary | H12: Nitin Jain | I12: Z00662398 | J12: 2410681 | K12: +91 8197683304 | L12: Primary | M12: Harsh Verma | N12: Z00666777 | O12: 2276537 | P12: +91 6395133167 | Q12: Secondary
A13: GPDM | H13: Pushpa Patil | I13: Z00666377 | J13: 2436313 | K13: +91 8208830014 | L13: Secondary | M13: Akriti Vats | N13: Z00662373 | O13: 2177684 | P13: +91 8510070608 | Q13: Secondary
A14: GPDM | M14: Sagar Kaware | N14: Z00664503 | O14: 696947 | P14: +49 15124631682 | Q14: Secondary
A15: GPDM/QDOK | H15: Jhansi Gowroju | I15: Z00662626 | J15: 2424270 | K15: +91 8498809471 | L15: Primary | M15: Nikhil Bhiste | N15: Z00662944 | O15: 2425958 | P15: +91 8149828774 | Q15: Primary
A16: GPDM
A17: NA | B17: Ravi / Ritesh | C17: Vaibhav Kolekar | D17: Z00662381 | E17: 2261809 | F17: +91 9067233323 | G17: Primary | H17: Pushpa Patil | I17: Z00666377 | J17: 2436313 | K17: +91 8208830014 | L17: Primary | M17: Akriti Vats | N17: Z00662373 | O17: 2177684 | P17: +91 8510070608 | Q17: Primary | R17: Gowthami Konduri | S17: Z00666701 | T17: 2068067 | U17: +1 4376613375 | V17: Secondary
A18: NA | C18: Shashank Purohit | D18: Z00662372 | E18: 2134110 | F18: +91 8826245403 | G18: Secondary | H18: Prasanthi Allam | I18: Z00662385 | J18: 2276700 | K18: +91 6300723778 | L18: Secondary | M18: Harsh Verma | N18: Z00666777 | O18: 2276537 | P18: +91 6395133167 | Q18: Primary
A19: NA | H19: Shahabaz Patel | I19: Z00664502 | J19: 2003109 | K19: +91 7350807999 | L19: Secondary | M19: Venkata Subba Reddy Varra | N19: Z00662945 | O19: 2425983 | P19: +91 7036172413 | Q19: Secondary
A20: NA | H20: Nitin Jain | I20: Z00662398 | J20: 2410681 | K20: +91 8197683304 | L20: Secondary | M20: Bhargavi Alapati | N20: Z00663739 | O20: 2428440 | P20: +91 7702394457 | Q20: Secondary
A21: NA | M21: Sagar Kaware | N21: Z00664503 | O21: 696947 | P21: +49 15124631682 | Q21: Secondary
A22: NA

Sheet Seebuger L1.5
C1: Shift Roster for Dec - 2025
A2: Associate Name | B2: Email | C2: Contact | D2: 45992 | E2: 45993 | F2: 45994 | G2: 45995 | H2: 45996 | I2: 45997 | J2: 45998 | K2: 45999 | L2: 46000 | M2: 46001 | N2: 46002 | O2: 46003 | P2: 46004 | Q2: 46005 | R2: 46006 | S2: 46007 | T2: 46008 | U2: 46009 | V2: 46010 | W2: 46011 | X2: 46012 | Y2: 46013 | Z2: 46014 | AA2: 46015 | AB2: 46016 | AC2: 46017 | AD2: 46018 | AE2: 46019 | AF2: 46020 | AG2: 46021 | AH2: 46022 | AI2: 46023 | AJ2: 46024 | AK2: 46025 | AL2: 46026 | AM2: 46027 | AN2: 46028 | AO2: 46029 | AP2: 46030 | AQ2: 46031 | AR2: 46032 | AS2: 46033 | AT2: 46034 | AU2: 46035 | AV2: 46036 | AW2: 46037 | AX2: 46038 | AY2: 46039 | AZ2: 46040 | BA2: 46041 | BB2: 46042 | BC2: 46043 | BD2: 46044 | BE2: 46045 | BF2: 46046 | BG2: 46047 | BH2: 46048 | BI2: 46049 | BJ2: 46050 | BK2: 46051 | BL2: 46052 | BM2: 46053
D3: =TEXT(D2,"DDD") -> Mon | E3: =TEXT(E2,"DDD") -> Tue | F3: =TEXT(F2,"DDD") -> Wed | G3: =TEXT(G2,"DDD") -> Thu | H3: =TEXT(H2,"DDD") -> Fri | I3: =TEXT(I2,"DDD") -> Sat | J3: =TEXT(J2,"DDD") -> Sun | K3: =TEXT(K2,"DDD") -> Mon | ... BM3: =TEXT(BM2,"DDD") -> Sat
A4: Esakkiappan | B4: esakkiappan.meenakshisundaram@freseniusmedicalcare.com | C4: +91 9566096398 | D4: General | E4: General | F4: General | G4: General | H4: General | I4: General | J4: General | K4: Night | L4: Night | M4: Night | N4: Night | O4: Night | P4: WO | Q4: WO | R4: Night | S4: Night | T4: Night | U4: Night | V4: Night | W4: WO | X4: WO | Y4: Morning | Z4: Morning | AA4: Morning | AB4: Leave | AC4: Leave | AD4: WO | AE4: WO | AF4: Morning | AG4: Morning | AH4: Morning | AI4: General | AJ4: General | AK4: WO | AL4: WO | AM4: General | AN4: General | AO4: General | AP4: WO | AQ4: WO | AR4: General | AS4: General | AT4: General | AU4: General | AV4: General | AW4: General | AX4: WO | AY4: WO | AZ4: General | BA4: General | BB4: General | BC4: General | BD4: General | BE4: General | BF4: WO | BG4: WO | BH4: General | BI4: General | BJ4: General | BK4: General | BL4: WO | BM4: WO
A5: Sampada | B5: sampada.shahapure@freseniusmedicalcare.com | C5: +91 9421247964 | D5: General | E5: General | F5: General | G5: General | H5: Leave | I5: WO | J5: WO | K5: Morning | L5: Morning | M5: General | N5: General | O5: General | P5: WO | Q5: WO | R5: Morning | S5: Morning | T5: Morning | U5: Morning | V5: Morning | W5: WO | X5: WO | Y5: Night | Z5: Night | AA5: Night | AB5: Night | AC5: Night | AD5: WO | AE5: WO | AF5: General | AG5: General | AH5: General | AI5: Morning | AJ5: Morning | AK5: Morning | AL5: Morning | AM5: WO | AN5: WO | AO5: Morning | AP5: Morning | AQ5: Morning | AR5: Morning | AS5: Morning | AT5: Morning | AU5: Morning | AV5: Morning | AW5: Morning | AX5: Morning | AY5: WO | AZ5: WO | BA5: Morning | BB5: Morning | BC5: Morning | BD5: Morning | BE5: Morning | BF5: WO | BG5: WO | BH5: Morning | BI5: Morning | BJ5: Morning | BK5: Morning | BL5: Morning | BM5: WO
A6: Remijious | B6: remijious.jebamalai@freseniusmedicalcare.com | C6: +91 9790793543 | D6: Night | E6: Night | F6: Night | G6: Night | H6: Night | I6: Night | J6: Night | K6: WO | L6: WO | M6: Morning | N6: Morning | O6: Morning | P6: WO | Q6: WO | R6: General | S6: General | T6: General | U6: General | V6: Leave | W6: WO | X6: WO | Y6: General | Z6: General | AA6: General | AB6: Leave | AC6: General | AD6: WO | AE6: WO | AF6: Night | AG6: Night | AH6: Night | AI6: Night | AJ6: Night | AK6: Night | AL6: Night | AM6: Night | AN6: WO | AO6: WO | AP6: Night | AQ6: Night | AR6: Night | AS6: Night | AT6: Night | AU6: Night | AV6: WO | AW6: WO | AX6: Night | AY6: Night | AZ6: Night | BA6: Night | BB6: Night | BC6: WO | BD6: WO | BE6: Night | BF6: Night | BG6: Night | BH6: Night | BI6: WO | BJ6: WO | BK6: Night | BL6: Night | BM6: Night
A7: Sneha | B7: sneha.m@freseniusmedicalcare.com | C7: +91 9092429640 | D7: Night | E7: Night | F7: WO | G7: WO | H7: Night | I7: Night | J7: Night | K7: Night | L7: Night | M7: WO | N7: WO | O7: Night | P7: Night | Q7: Night | R7: Night | S7: Night | T7: WO | U7: WO | V7: Night | W7: Night | X7: Night | Y7: Night | Z7: Night | AA7: WO | AB7: WO | AC7: Night | AD7: Night | AE7: Night | AF7: Night | AG7: Night | AH7: WO | AI7: WO | AJ7: WO | AK7: General | AL7: General | AM7: General | AN7: General | AO7: General | AP7: General | AQ7: General | AR7: WO | AS7: WO | AT7: General | AU7: WO | AV7: WO | AW7: General | AX7: General | AY7: General | AZ7: General | BA7: General | BB7: WO | BC7: WO | BD7: General | BE7: General | BF7: General | BG7: General | BH7: General | BI7: WO | BJ7: WO | BK7: General | BL7: General | BM7: General
A8: Ayush | B8: ayush.kumar2@freseniusmedicalcare.com | C8: +91 7004996553 | D8: General | E8: General | F8: WO | G8: WO | H8: General | I8: General | J8: General | K8: General | L8: General | M8: WO | N8: WO | O8: General | P8: General | Q8: General | R8: General | S8: General | T8: WO | U8: WO | V8: General | W8: General | X8: General | Y8: General | Z8: WO | AA8: WO | AB8: General | AC8: General | AD8: General | AE8: General | AF8: General | AG8: General | AH8: WO | AI8: Night | AJ8: Night | AK8: WO | AL8: WO | AM8: Night | AN8: Night | AO8: Night | AP8: Night | AQ8: Night | AR8: WO | AS8: WO | AT8: Night | AU8: Night | AV8: WO | AW8: WO | AX8: Night | AY8: Night | AZ8: Night | BA8: Night | BB8: Night | BC8: Night | BD8: Night | BE8: Night | BF8: WO | BG8: WO | BH8: Night | BI8: Night | BJ8: Night | BK8: Night | BL8: Night | BM8: WO
A9: Padma (Backup) | B9: venkatapadmavathi.thota@freseniusmedicalcare.com | R9: General | S9: General | T9: WO | U9: WO | V9: General | W9: General | X9: General | Y9: General | Z9: WO | AA9: WO | AB9: General | AC9: General | AD9: General | AE9: General | AF9: General | AG9: WO | AH9: WO
A10: Anushah( Backup) | B10: nirmala.s@freseniusmedicalcare.com | R10: General | S10: General | T10: General | U10: General | V10: General | W10: WO | X10: WO | Y10: General | Z10: General | AA10: General | AB10: General | AC10: General | AD10: WO | AE10: WO | AF10: General | AG10: General
A14: Shift Details
A15: Morning | B15: 06:00 AM - 04:00 PM (IST) 01:30 AM - 11:30 AM (CET) 07:30 AM - 05:30 AM (EST)
A16: General | B16: 12:30 PM - 10:30 PM (IST) 08:00 AM - 06:00 PM (CET) 02:00 AM - 12:00 PM(EST)
A17: Night | B17: 10:00 PM - 8:00 AM (IST) 05-30 PM - 03:30 AM (CET) 11:30 AM - 09:30 PM (EST)

Sheet CE Team Summary
A1: App ID | B1: App Name | C1: Support Assignment Group/Project Name(QuickService) | D1: Type | E1: FME App Owner | F1: ITSM Tool | G1: FME IT LEAD | H1: Cognizant App Owner Name | I1: Cognizant App Primary POC | J1: Team Member Names | K1: MI Teams Call Access Requested for key resources | L1: Request Status | M1: FME IT Lead name is validated by CTS lead? | N1: Add FME Lead contact details | O1: CTS Lead discussed the MI Process with FME Lead | Q1: Business Service Offering | R1: TAG | S1: Assignment Group
A2: 906 | B2: Azure: ICC External Portal | C2: ITS-GLOBAL-BPI-ICC_Sharepoint-L2 | D2: 8x5 | E2: Ritesh Nagori | F2: ServiceNow | G2: andreas.klaus@freseniusmedicalcare.com | H2: Vinish Kumar vinishkumar.v.m@cognizant.com | I2: Vinish Kumar vinishkumar.v.m@cognizant.com | J2: Vinishkumar Yasaswini Biragi Ravichandran | K2: Vinish Kumar | L2: Access Acquired | M2: Yes | N2: 491725346044
A3: 116 | B3: Azure: ICC Portal | C3: ITS-GLOBAL-BPI-ICC_Sharepoint-L2 | D3: 8x5 | E3: Ritesh Nagori | F3: ServiceNow | G3: andreas.klaus@freseniusmedicalcare.com | H3: Vinish Kumar vinishkumar.v.m@cognizant.com | I3: Vinish Kumar vinishkumar.v.m@cognizant.com | J3: Silpa C | K3: Vinish Kumar | L3: Access Acquired | M3: Yes | N3: 491725346044
A4: 907 | B4: Azure: ICC Training Material | C4: ITS-GLOBAL-BPI-ICC_Sharepoint-L2 | D4: 8x5 | E4: Ritesh Nagori | F4: ServiceNow | G4: andreas.klaus@freseniusmedicalcare.com | H4: Vinish Kumar vinishkumar.v.m@cognizant.com | I4: Vinish Kumar vinishkumar.v.m@cognizant.com | J4: Ravichandran Ponnuswamy Vinish Kumar | K4: Vinish Kumar | L4: Access Acquired | M4: Yes | N4: 491725346044
A5: 120 | B5: JIRA - FME EQMS | C5: ITS-GLOBAL-ADEX-CE_BXS_JIRA-L2 ITS-GLOBAL-ADEX-CE_BXS_JIRA-L3 | D5: 8x5 | E5: Ritesh Nagori | F5: ServiceNow | G5: mahammed.zubair@freseniusmedicalcare.com | H5: Vinish Kumar vinishkumar.v.m@cognizant.com | I5: Vinish Kumar vinishkumar.v.m@cognizant.com | J5: Vinish Kumar Vaishali Patel Jeevan Empati | K5: Jeevan Empati | L5: Access Acquired | M5: Yes
A6: 121 | B6: JIRA - FME QREM - CAPA Management | C6: ITS-GLOBAL-ADEX-CE_BXS_JIRA-L2 ITS-GLOBAL-ADEX-CE_BXS_JIRA-L3 | D6: 8x5 | E6: Ritesh Nagori | F6: ServiceNow | G6: Fatima.Raza@freseniusmedicalcare.com | H6: Vinish Kumar vinishkumar.v.m@cognizant.com | I6: Vinish Kumar vinishkumar.v.m@cognizant.com | J6: Vinish Kumar Vaishali Patel Jeevan Empati | K6: Jeevan Empati | L6: Access Acquired | M6: Yes
A7: 122 | B7: JIRA / Service Desk - FME Technet/HR Operations | C7: ITS-GLOBAL-ADEX-CE_BXS_JIRA-L2 ITS-GLOBAL-ADEX-CE_BXS_JIRA-L3 | D7: 24x5 | E7: Ritesh Nagori | F7: ServiceNow | G7: mahammed.zubair@freseniusmedicalcare.com | H7: Vinish Kumar vinishkumar.v.m@cognizant.com | I7: Vinish Kumar vinishkumar.v.m@cognizant.com | J7: Vinish Kumar Vaishali Patel Jeevan Empati | K7: Jeevan Empati | L7: Access Acquired | M7: Yes
A8: 114 | B8: Salesforce Integrations (US CE Commercial) | C8: DTI-ECOE-NA RTG Salesforce Support | D8: 16x5 | E8: Suresh Madhwapathy | F8: ServiceNow | G8: Charles.McField@freseniusmedicalcare.com | H8: Sagar Solanki Sagar.Solanki@cognizant.com | I8: Varsha Hariharan Varsha.Hariharan@cognizant.com | J8: Varsha Hariharan Vinay Kumar (onsite) | K8: Varsha Hariharan | L8: Access Acquired | M8: Yes | N8: +1 8574246599 | O8: Yes
A9: 133 | B9: Clinic Backroom Supply (RTG Orders / RTG Supplies) | C9: DTI-ECOE-NA RTG Salesforce Support | D9: 16x5 | E9: Suresh Madhwapathy | F9: ServiceNow | G9: Cindy.Gartley@freseniusmedicalcare.com | H9: Sagar Solanki Sagar.Solanki@cognizant.com | I9: Varsha Hariharan Varsha.Hariharan@cognizant.com | J9: Varsha Hariharan Rohit Prasad Vinay Kumar (onsite) | K9: Varsha Hariharan | L9: Access Acquired | M9: Yes | N9: +1 8574246599 | O9: Yes
A10: 134 | B10: SalesForce (CE US Commercial) | C10: DTI-ECOE-NA RTG Salesforce Support | D10: 16x5 | E10: Suresh Madhwapathy | F10: ServiceNow | G10: Cindy.Gartley@freseniusmedicalcare.com | H10: Sagar Solanki Sagar.Solanki@cognizant.com | I10: Varsha Hariharan Varsha.Hariharan@cognizant.com | J10: Varsha Hariharan Vinay Kumar (onsite) | K10: Varsha Hariharan | L10: Access Acquired | M10: Yes | N10: +1 8574246599 | O10: Yes
A11: 135 | B11: Salesforce NxStage Medical | C11: DTI-GLOBAL-EUX-NxStage SalesForce - L3 | D11: 16x5 | E11: Duncan Stewart | F11: ServiceNow | G11: Duncan.Stewart@freseniusmedicalcare.com | H11: Sagar Solanki Sagar.Solanki@cognizant.com | I11: Varsha Hariharan Varsha.Hariharan@cognizant.com | J11: Varsha Hariharan Vinay Kumar (onsite) | K11: Varsha Hariharan | L11: Access Acquired | M11: Yes | N11: +1 7813545262 | O11: Yes
A12: 137 | B12: Salesforce - Conga (LATAM) | C12: DTI-LATAM-ALL-ADEX-Apttus-L1 | D12: 16x5 | E12: Ritesh Nagori | F12: ServiceNow | G12: ceres.tenenbaum@freseniusmedicalcare.com | H12: Sagar Solanki Sagar.Solanki@cognizant.com | I12: Rohit Prasad rohit.prasad3@cognizant.com | J12: Rohit Prasad Vinay Kumar (onsite) | K12: Rohit Prasad | L12: Access Acquired | M12: Yes | N12: +55 21 21790129 | O12: Yes
A13: 124 | B13: Mobile: CSM App | C13: DTI-Global-CAP-ADEX-Mobile_Application_Solutions - L2 DTI-Global -CAP-ADEX-Mobile_Application_Solutions - L3 | D13: 24x5 | E13: Ritesh Nagori | F13: ServiceNow | G13: joerg.ludwig@freseniusmedicalcare.com | H13: Arunprasath Arunprasath.S2@cognizant.com | I13: Thangappan, Arunpandi Arunpandi.Thangappan@cognizant.com | J13: Arunpandi Thangappan | K13: Arunpandi Thangappan | L13: Access Acquired | M13: Yes | N13: +49 1723199082 | O13: Yes
A14: 142 | B14: App Connect (Cast Iron) | C14: ITS-NA-EACOE-AppConnect-L1 | D14: 8x5 | E14: Ritesh Nagori | F14: ServiceNow | G14: Panthalarajan.Nagarethinam@freseniusmedicalcare.com | H14: Atanu Atanu.Sadhukhan@cognizant.com | I14: Srivarsha Gadipelli Srivarsha.Gadipelli@cognizant.com | J14: Srivarsha Gadipelli | K14: Srivarsha Gadipelli | L14: Access Acquired | M14: Yes | N14: +1 4086368906(Panthal) | O14: Yes
A15: 119 | B15: CQT - Configuration & Quotation Tool | C15: ITS-GLOBAL-ADEX-CQT_APP_SUPPORT-L2 | D15: 8x5 | E15: Ritesh Nagori | F15: ServiceNow | G15: Helena.Schmitz@freseniusmedicalcare.com andreas.klaus@freseniusmedicalcare.com | H15: Pooja PH Pooja.PH@cognizant.com | I15: Pooja PH Pooja.PH@cognizant.com | J15: Pooja PH Duvvi Vinod Kumar Deva Darshini S | K15: Pooja PH | L15: In Progress | M15: Yes | N15: +4961722686662(Andreas) +4961722685955 (Helena) | O15: Yes | P15: No Tickets
A16: 108 | B16: Polarion | C16: GPDM Polarion | D16: 24x5 | E16: Ritesh Nagori | F16: Quick Service | G16: renate.floeser@freseniusmedicalcare.com miklos.spirko@freseniusmedicalcare.com | H16: Nitin Jain Jain.Nitin@cognizant.com | I16: Sagar Kaware Sagar.Kaware@cognizant.com | J16: Sagar Kaware (onsite) Kaushik Kandagatla Diksha Kokadwar Gowthami Konduri (onsite) Divya Unnikrishnan (onsite) | K16: Goutam Bhadravti Mohan Sagar Kaware | L16: Access Acquired | M16: Yes | N16: +4961722688703 (Renate) +36 70 665 4366(Miklos) | O16: Yes
A17: 139 | B17: Salesforce - Conga (CE US Commercial) | C17: ITS-GLOBAL-ADEX-Conga_CLM-CPQ-L2 | D17: 16x5 | E17: Ritesh Nagori | F17: ServiceNow | G17: zachary.schuneman@freseniusmedicalcare.com | H17: Sagar Solanki Sagar.Solanki@cognizant.com | I17: Rohit Prasad rohit.prasad3@cognizant.com | J17: Rohit Prasad Vinay Kumar (onsite) | K17: Rohit Prasad | L17: Access Acquired | M17: Yes | N17: +1 440-941-7383 | O17: Yes
A18: 999 | B18: Salesforce Health Cloud - Shield, Field Service Lightning | C18: DTI-ECOE-NA RTG Salesforce Support | D18: 16x5 | E18: Suresh Madhwapathy | F18: ServiceNow | G18: Charles.McField@freseniusmedicalcare.com | H18: Sagar Solanki Sagar.Solanki@cognizant.com | I18: Varsha Hariharan Varsha.Hariharan@cognizant.com | J18: Varsha Hariharan Vinay Kumar (onsite) | K18: Varsha Hariharan | L18: Access Acquired | M18: Yes | N18: +1 8574246599 | O18: Yes
A19: 117 | B19: BI SQL Cluster / FME - Epur | C19: ITS-GLOBAL-ADEX-BI_CE-L2 | D19: 8x5 | E19: Ritesh Nagori | F19: ServiceNow | G19: eric.lucas@freseniusmedicalcare.com | H19: Rajesh Kumar E RajeshKumar.E@cognizant.com | I19: Rajesh Kumar E RajeshKumar.E@cognizant.com | J19: Rajesh Kumar E Ganesh G A, Prasanth | K19: Rajesh Kumar E | L19: Access Acquired | M19: Yes | N19: Eric Lucas <eric.lucas@freseniusmedicalcare.com> +1-508-688-7158 | O19: Yes
A20: 112 | B20: PTC Windchill GPDM | C20: GPDM Windchill | D20: 24x5 | E20: Jeffrey Norton | F20: Quick Service | G20: ravi.vuta@freseniusmedicalcare.com | H20: Nitin Jain Jain.Nitin@cognizant.com | I20: Nitin Jain Jain.Nitin@cognizant.com | J20: Nitin Jain Bhargavi Alapati Venkata Subba Reddy Varra Shashank Purohit Vinoth Kumar Gourav Kumar P Gowthami Konduri (onsite) Divya Unnikrishnan (onsite) | K20: Nitin Jain | L20: Access Acquired | M20: Yes | N20: Ravi Vuta: +17816909434 (mobile) +17816992739 (office) | O20: Yes
A21: 913 | B21: PTC CREO | C21: GPDM Windchill | D21: 24x5 | E21: Jeffrey Norton | F21: Quick Service | G21: ravi.vuta@freseniusmedicalcare.com | H21: Nitin Jain Jain.Nitin@cognizant.com | I21: Divya Unnikrishnan divya.unnikrishnan@cognizant.com | J21: Nikhil Bhiste Divya Unnikrishnan (onsite) Gowthami Konduri (onsite) | K21: Nikhil Bhiste | L21: Access Acquired | M21: Yes | N21: Ravi Vuta: +17816909434 (mobile) +17816992739 (office) | O21: Yes
A22: 106 | B22: Artifactory | C22: GPDM Engineering Tools | D22: 24x5 | E22: Harald Villinger | F22: Quick Service | G22: harald.villinger@freseniusmedicalcare.com | H22: Pradip Kumar Pradip.Dhak@cognizant.com | I22: Naren Elango Naren.Elango@cognizant.com | J22: Naren Elango | K22: Naren Elango | L22: Access Acquired | M22: Yes | N22: Work : +49 972167841080 Email : harald.villinger@freseniusmedicalcare.com | O22: Yes ,Harald is checking internally on existing process | P22: App is listed as 24X5 , we have concurrence from Harald to operate in single shift for some time based on volume we will add people across shifts. Shared the email with Ritesh for reference
A23: 537 | B23: GPDM Subversion | C23: GPDM Engineering Tools | D23: 24x5 | E23: harald.villinger_x000D_ michael.baunach | F23: Quick Service | G23: harald.villinger@freseniusmedicalcare.com michael.baunach@freseniusmedicalcare.com | H23: Thiruvengadam Thiruvengadam.TC@cognizant.com | I23: Naren Elango Naren.Elango@cognizant.com | J23: Naren Elango | K23: Naren Elango | L23: Access Acquired | M23: Yes | N23: Work : +49 972167841080 Email : harald.villinger@freseniusmedicalcare.com | O23: Yes ,Harald is checking internally on existing process
A24: 538 | B24: gpm-jenkins-prod-Diamond | C24: GPDM Engineering Tools | D24: 24x5 | E24: Thorsten Boecker | F24: Quick Service | G24: thorsten.boecker@freseniusmedicalcare.com | H24: Pradip Kumar Pradip.Dhak@cognizant.com | I24: Naren Elango Naren.Elango@cognizant.com | J24: Naren Elango | K24: Naren Elango | L24: Access Acquired | M24: Yes | N24: Work : +49 972167841080 Email : harald.villinger@freseniusmedicalcare.com | O24: Yes ,Harald is checking internally on existing process | P24: App is listed as 24X5 , we have concurrence from Harald to operate in single shift for some time based on volume we will add people across shifts. Shared the email with Ritesh for reference
A25: 152 | B25: VIIMA | C25: ITS-GLOBAL-ADEX-VIIMA-L2 | D25: 8x5 | E25: Sabrina Nyugen | F25: ServiceNow | G25: Olivier.deBruijn@freseniusmedicalcare.com | H25: Naren Elango Naren.Elango@cognizant.com | I25: Naren Elango Naren.Elango@cognizant.com | J25: Naren Elango | K25: Naren Elango | L25: Access Acquired | M25: Updated | N25: Work:+41 79 627 53 00 olivier.debruijn@freseniusmedicalcare.com | O25: Yes
A26: 908 | B26: IQVIA RIMS | C26: Regulatory Information Management system | D26: 24x5 | E26: Ritesh Nagori | F26: Quick Service | G26: guruprasad.subbarayalu@freseniusmedicalcare.com | H26: Manjunath R Manjunath.R3@cognizant.com | I26: Nagraj LNU Nagraj.LNU@cognizant.com | J26: Nagraj LNU Manjunath R Sreevarsha Vuppala Vinod B Kumar Sai Nivedita Venishetty (onsite) | K26: SaiNivedita Venishetty | L26: Access Acquired | M26: Yes | N26: +1 6506953691 | O26: Yes
A27: 111 | B27: Trackwise (QTRAK) | C27: QTRAK ServiceDesk | D27: 24x5 | E27: Ritesh Nagori | F27: Quick Service | G27: guruprasad.subbarayalu@freseniusmedicalcare.com | H27: Manjunath R Manjunath.R3@cognizant.com | I27: Nagraj LNU Nagraj.LNU@cognizant.com | J27: Nagraj LNU Manjunath R Sreevarsha Vuppala Vinod B Kumar Sai Nivedita Venishetty (onsite) | K27: Nagraj LNU | L27: Access Acquired | M27: Yes | N27: +1 6506953691 | O27: Yes
A28: 150 | B28: Modern Requirements | C28: ITS-GLOBAL-ADEX-Modern_Req-L2 | D28: 8x5 | E28: Jeffrey Norton | F28: ServiceNow | G28: Olivier.deBruijn@freseniusmedicalcare.com | H28: Murali Yenamala Gopala.YenamalaMurali@cognizant.com | I28: Murali Yenamala Gopala.YenamalaMurali@cognizant.com | J28: Murali Yenamala (onsite) Pooja PH | K28: Murali Yenamala | L28: Access Acquired | M28: Yes | N28: +41 79 627 53 00 | O28: Yes | P28: No Tickets
A29: 140 | B29: Seeburger | C29: DTI-EACOE-EDI Seeburger - L1 ITS-GLOBAL-ADEX-Seeburger-L2 | D29: 24x7 | E29: Ritesh Nagori | F29: ServiceNow | G29: kondal.reddy.kasireddy@freseniusmedicalcare.com | H29: Atanu Atanu.Sadhukhan@cognizant.com | I29: Joyson A Joyson.A@cognizant.com | J29: Joyson A Ravi Babu Gurram AbdulKalam Akula (onsite) | K29: Joyson A | L29: Access Acquired | M29: Yes | N29: +1 6313747158 | O29: Yes
A30: 109 | B30: PTC ThingWorx (Global Product Risk Tool) | C30: GPDM Windchill | D30: 24x5 | E30: Renate Floeser | F30: Quick Service | G30: surender-reddy.muddam@freseniusmedicalcare.com | H30: Nitin Jain Jain.Nitin@cognizant.com | I30: Gowthami Konduri Gowthami.Konduri@cognizant.com | J30: Manoj Yamala Anoop Sarkar Gowthami Konduri (onsite) Divya Unnikrishnan (onsite) | K30: Gowthami Konduri | L30: Access Acquired | M30: Yes | N30: Surender Reddy Muddam: Work: +499721678776 Mobile: +491723823864 | O30: Yes
A31: 127 | B31: Mobile: One App | C31: DTI-Global-CAP-ADEX-Mobile_Application_Solutions - L2 DTI-Global -CAP-ADEX-Mobile_Application_Solutions - L3 | D31: 8x5 | E31: Ritesh Nagori | F31: ServiceNow | G31: ildiko-kinga.peter@freseniusmedicalcare.com | H31: Arunprasath Arunprasath.S2@cognizant.com | I31: Arunprasath Arunprasath.S2@cognizant.com | J31: Arunprasath Sivasamy | K31: Arunprasath Sivasamy | L31: Access Acquired | M31: Yes | N31: +49 1511 8400742 | O31: Yes
A32: 128 | B32: Mobile: One App Desktop | C32: DTI-Global-CAP-ADEX-Mobile_Application_Solutions - L2 DTI-Global -CAP-ADEX-Mobile_Application_Solutions - L3 | D32: 8x5 | E32: Ritesh Nagori | F32: ServiceNow | G32: ildiko-kinga.peter@freseniusmedicalcare.com | H32: Arunprasath Arunprasath.S2@cognizant.com | I32: Arunprasath Arunprasath.S2@cognizant.com | J32: Arunprasath Sivasamy | K32: Arunprasath Sivasamy | L32: Access Acquired | M32: Yes | N32: +49 1511 8400742 | O32: Yes
A33: 129 | B33: Mobile: PID | C33: DTI-Global-CAP-ADEX-Mobile_Application_Solutions - L2 DTI-Global -CAP-ADEX-Mobile_Application_Solutions - L3 | D33: 8x5 | E33: Ritesh Nagori | F33: ServiceNow | G33: alexander.wagner@freseniusmedicalcare.com | H33: Arunprasath Arunprasath.S2@cognizant.com | I33: Arunprasath Arunprasath.S2@cognizant.com | J33: Arunprasath Sivasamy | K33: Arunprasath Sivasamy | L33: Access Acquired | M33: Yes | N33: M +49 162 488 26 12 | O33: Yes
A34: 518 | B34: SleepSafeHarmony 2 EN | C34: DTI-Global-CAP-ADEX-Mobile_Application_Solutions - L2 DTI-Global -CAP-ADEX-Mobile_Application_Solutions - L3 | D34: 16x5 | E34: Ritesh Nagori | F34: ServiceNow | G34: ildiko-kinga.peter@freseniusmedicalcare.com | H34: Arunprasath Arunprasath.S2@cognizant.com | I34: Arunprasath Arunprasath.S2@cognizant.com | J34: Arunprasath Sivasamy | K34: Arunprasath Sivasamy | L34: Access Acquired | M34: Yes | N34: M +49 162 488 26 12 | O34: Yes
A35: 535 | B35: Global ComplianceWire - Quality & Regulatory Training | C35: Compliance Wire | D35: 8x5 | E35: dirk.malland@freseniusmedicalcare.com | F35: Quick Service | G35: amy.green@freseniusmedicalcare.com | H35: Arun Kumar S Arun.KumarS4@cognizant.com | I35: Arun Kumar S Arun.KumarS4@cognizant.com | J35: Arun Kumar S | K35: Arun Kumar S | L35: Access Acquired | M35: Yes | N35: 617-513-7704 | O35: Yes
A36: 113 | B36: PTC Windchill NA | C36: DTI-EACOE-Windchill IT - L2 | D36: 24x5 | E36: Ravi Vuta | F36: ServiceNow | G36: ravi.vuta@freseniusmedicalcare.com | H36: Nitin Jain Jain.Nitin@cognizant.com | I36: Akriti Vats Akriti.Vats@cognizant.com | J36: Akriti Vats Vaibhav Kolekar Pushpa Gajanan Patil Prasanthi Allam Divya Unnikrishnan (onsite) Gowthami Konduri (onsite) | K36: Divya Unnikrishnan Akriti Vats | L36: Access Acquired | M36: Yes | N36: Ravi Vuta: +17816909434 (mobile) +17816992739 (office) | O36: Yes

Sheet IMS AWS Team
A1: SHIFT AND ONCALL SCHEDULE (Off-Shore Cloud Infrastructure Operations team) IO | H1: OC-P = On Call Primary | I1: ( Only support through On-Call) | K1: On-Call Start (CEST) | L1: On-Call Finsh(CEST) | M1: On-Call Start (IST) | N1: On-Call Finsh(IST)
H2: OC-S = On Call Seconday | I2: ( Only support through On-Call) | J2: Monday - Friday: | K2: 0.77083333 | L2: 03:00 AM (Next Day) | M2: 0.91666667 | N2: 06:30 AM (Next Day)
H3: OC = A2 + On-call( 10.00PM to 06.30 AM) | J3: Saturday: | K3: 0.27083333 | L3: 06:30 AM (Next Day) | M3: 0.27083333 | N3: 06:30 AM (Next Day)
H4: A1 = 06:30 AM to 04:30 PM (IST) | J4: Sunday: | K4: 0.27083333 | L4: 3:00 AM (Next Day) | M4: 0.27083333 | N4: 06:30 AM (Next Day)
H5: A2= 10:00 AM to 08:00 PM (IST)
H6: A3 = 12:00 PM to 10.00 PM (IST)
H7: WO = Week Off
H8: PH = Public Holiday | I8: IO Escalation POC
H9: PL = Planned Leave | I9: Arun Kumar Vellaichamy: +919940414358
H10: EL = Emergency Leave | I10: Sunil Kumar Panigrahi : +91 7829725164
H11: SL = Sick Leave
A14: Resource name | C14: Arun.Vellaichamy | D14: Hemalatha.Rajagopalan | E14: Brajaballav.Nath | F14: Shagun.Singh | G14: Krishna.Sahu | H14: Ishani.Mishra | I14: Ragupathi.Shangmugam
A15: Location | C15: Chennai | D15: Chennai | E15: Bangalore | F15: Noida | G15: Hydrebad | H15: Bangalore | I15: Coimbatore
A16: Contact No. | C16: +91 9940414358 | D16: +91 9597259025 | E16: +91 8329147932 | F16: +91 8278797577 | G16: +91 9691718934 | H16: +91-9337531233 | I16: +91 8825641617
A17: Date | B17: Day
A18: 46174 | B18: Monday | C18: PL | D18: A3 | E18: OC | F18: A3 | G18: PL | H18: A1 | I18: A2
A19: 46175 | B19: Tuesday | C19: PL | D19: A3 | E19: OC | F19: A3 | G19: PH | H19: A1 | I19: A2
A20: 46176 | B20: Wednesday | C20: PL | D20: A3 | E20: OC | F20: A3 | G20: PL | H20: A1 | I20: PL
A21: 46177 | B21: Thursday | C21: PL | D21: PL | E21: OC | F21: A3 | G21: PL | H21: A1 | I21: A2
A22: 46178 | B22: Friday | C22: PL | D22: A3 | E22: OC | F22: A3 | G22: PL | H22: A1 | I22: A2
A23: 46179 | B23: Saturday | C23: WO | D23: WO | E23: OC-P | F23: WO | G23: WO | H23: OC-S | I23: WO
A24: 46180 | B24: Sunday | C24: WO | D24: WO | E24: OC-P | F24: WO | G24: WO | H24: OC-S | I24: WO
A25: 46181 | B25: Monday | C25: A3 | D25: A1 | E25: A2 | F25: OC | G25: PL | H25: A3 | I25: A3
A26: 46182 | B26: Tuesday | C26: A3 | D26: A1 | E26: A2 | F26: A2 | G26: OC | H26: A3 | I26: A3
A27: 46183 | B27: Wednesday | C27: A3 | D27: A1 | E27: A2 | F27: A2 | G27: OC | H27: A3 | I27: A3
A28: 46184 | B28: Thursday | C28: A3 | D28: A1 | E28: A2 | F28: A2 | G28: OC | H28: A3 | I28: A3
A29: 46185 | B29: Friday | C29: A3 | D29: A1 | E29: A2 | F29: A2 | G29: OC | H29: A3 | I29: A3
... A47: 46203 | B47: Tuesday | C47: A3 | D47: A3 | E47: A2 | F47: OC | G47: A3 | H47: A2 | I47: A1

Sheet L 1.5 - Seeburger
A1: Associate Name | B1: Email | C1: Contact | D1: Mon 01 | E1: Tue 02 | F1: Wed 03 | G1: Thu 04 | H1: Fri 05 | I1: Sat 06 | J1: Sun 07 | K1: Mon 08 | L1: Tue 09 | M1: Wed 10 | N1: Thu 11 | O1: Fri 12 | P1: Sat 13 | Q1: Sun 14 | R1: Mon 15 | S1: Tue 16 | T1: Wed 17 | U1: Thu 18 | V1: Fri 19 | W1: Sat 20 | X1: Sun 21 | Y1: Mon 22 | Z1: Tue 23 | AA1: Wed 24 | AB1: Thu 25 | AC1: Fri 26 | AD1: Sat 27 | AE1: Sun 28 | AF1: Mon 29 | AG1: Tue 30
A3: Padma Thota | B3: S1 | C3: S1 | D3: S1 | E3: OFF | F3: OFF | G3: S1 | H3: S1 | I3: S1 | J3: S1 | K3: OFF | L3: OFF | M3: S1.5 | N3: S1.5 | O3: S1.5 | P3: S1.5 | Q3: S1.5 | R3: OFF | S3: S1 | T3: S1 | U3: OFF | V3: OFF | W3: S1 | X3: S1 | Y3: S1.5 | Z3: OFF | AA3: OFF | AB3: P.Leave | AC3: S1.5 | AD3: S1.5 | AE3: S2 | AF3: S2 | AG3: S2
A4: Sneha | B4: S1 | C4: S1 | D4: S5 | E4: S5 | F4: S5 | G4: S5 | H4: S5 | I4: OFF | J4: OFF | K4: S5 | L4: S5 | M4: S5 | N4: S5 | O4: S5 | P4: OFF | Q4: OFF | R4: S5 | S4: S5 | T4: S5 | U4: S5 | V4: S5 | W4: OFF | X4: OFF | Y4: S5 | Z4: S5 | AA4: S5 | AB4: S5 | AC4: S5 | AD4: OFF | AE4: OFF | AF4: S5 | AG4: S5
A5: Anushah | B5: S1.5 | C5: S1.5 | D5: S1 | E5: S1 | F5: S1 | G5: S1 | H5: S1 | I5: OFF | J5: OFF | K5: S1 | L5: S1 | M5: S1 | N5: S1 | O5: S1 | P5: OFF | Q5: OFF | R5: S1 | S5: P.Leave | T5: P.Leave | U5: S1 | V5: S1 | W5: OFF | X5: OFF | Y5: S1 | Z5: OFF | AA5: OFF | AB5: S1 | AC5: S1 | AD5: S1 | AE5: S1 | AF5: S1 | AG5: S1
A6: Arunprashanth | B6: OFF | C6: OFF | D6: S3 | E6: S3 | F6: S3 | G6: S3 | H6: S3 | I6: OFF | J6: OFF | K6: S3 | L6: S3 | M6: S3 | N6: S3 | O6: S3 | P6: OFF | Q6: OFF | R6: S3 | S6: S3 | T6: S3 | U6: S3 | V6: S3 | W6: OFF | X6: OFF | Y6: S3 | Z6: S3 | AA6: S3 | AB6: S3 | AC6: S3 | AD6: OFF | AE6: OFF | AF6: S3 | AG6: S3
A7: Sivakumar | B7: S5 | C7: S5 | D7: S2 | E7: OFF | F7: OFF | G7: S2 | H7: S2 | I7: S2 | J7: S2 | K7: S2 | L7: S2 | M7: OFF | N7: OFF | O7: S2 | P7: S2 | Q7: S2 | R7: S2 | S7: OFF | T7: OFF | U7: S2 | V7: S1.5 | W7: S2 | X7: S2 | Y7: S2 | Z7: S1 | AA7: S1 | AB7: OFF | AC7: OFF | AD7: S5 | AE7: S5 | AF7: OFF | AG7: S2
